2023-03-11 22:03:05,878 [INFO   ] [APP] at_arb started with arguments={rtg.py, run, at_arb.py}
2023-03-11 22:03:05,878 [INFO   ] [APP] configuration={"Execution":{"Host":"127.0.0.1","Port":12345},"Information":{"Type":"mmap","Name":"info.dat"},"TeamName":"Trader_Arb","Secret":"secret"}
2023-03-11 22:03:05,880 [INFO   ] [CONNECTION] fd=16 connection established: peer=127.0.0.1:12345
2023-03-11 22:03:10,224 [INFO   ] [TRADER] received order book for instrument 0 with sequence number 1
2023-03-11 22:03:10,228 [ERROR  ] [RECEIVER] connection lost:
Traceback (most recent call last):
  File "/Users/nves/Downloads/pyready_trader_go/ready_trader_go/pubsub.py", line 136, in _subscribe_worker
    protocol.datagram_received(buffer[start:start + length], from_addr)
  File "/Users/nves/Downloads/pyready_trader_go/ready_trader_go/messages.py", line 212, in datagram_received
    self.on_datagram(typ, data, HEADER_SIZE, length)
  File "/Users/nves/Downloads/pyready_trader_go/ready_trader_go/base_auto_trader.py", line 69, in on_datagram
    self.on_order_book_update_message(inst, seq, *BOOK_PART.iter_unpack(data[ORDER_BOOK_HEADER_SIZE:]))
  File "/Users/nves/Downloads/pyready_trader_go/at_arb.py", line 101, in on_order_book_update_message
    if ((self.best_ask_trade - new_bid_price) / new_bid_price) > 0.01 and self.bid_id == 0 and new_bid_price != 0 and self.position < POSITION_LIMIT:
ZeroDivisionError: division by zero
2023-03-11 22:03:10,231 [INFO   ] [APP] closing event loop
2023-03-11 22:03:10,231 [INFO   ] [CONNECTION] fd=16 connection lost
2023-03-11 22:03:10,232 [ERROR  ] [asyncio] Exception in callback _SelectorSocketTransport._call_connection_lost(None)
handle: <Handle _SelectorSocketTransport._call_connection_lost(None)>
Traceback (most recent call last):
  File "/Library/Frameworks/Python.framework/Versions/3.10/lib/python3.10/asyncio/events.py", line 80, in _run
    self._context.run(self._callback, *self._args)
  File "/Library/Frameworks/Python.framework/Versions/3.10/lib/python3.10/asyncio/selector_events.py", line 984, in _call_connection_lost
    super()._call_connection_lost(exc)
  File "/Library/Frameworks/Python.framework/Versions/3.10/lib/python3.10/asyncio/selector_events.py", line 742, in _call_connection_lost
    self._protocol.connection_lost(exc)
  File "/Users/nves/Downloads/pyready_trader_go/ready_trader_go/base_auto_trader.py", line 59, in connection_lost
    Subscription.close(self)
  File "/Users/nves/Downloads/pyready_trader_go/ready_trader_go/messages.py", line 186, in close
    self._receiver_transport.close()
AttributeError: 'NoneType' object has no attribute 'close'
2023-03-11 22:03:53,154 [INFO   ] [APP] at_arb started with arguments={rtg.py, run, at_arb.py}
2023-03-11 22:03:53,154 [INFO   ] [APP] configuration={"Execution":{"Host":"127.0.0.1","Port":12345},"Information":{"Type":"mmap","Name":"info.dat"},"TeamName":"Trader_Arb","Secret":"secret"}
2023-03-11 22:03:53,156 [INFO   ] [CONNECTION] fd=16 connection established: peer=127.0.0.1:12345
2023-03-11 22:03:57,787 [INFO   ] [TRADER] received order book for instrument 0 with sequence number 1
2023-03-11 22:03:57,787 [ERROR  ] [RECEIVER] connection lost:
Traceback (most recent call last):
  File "/Users/nves/Downloads/pyready_trader_go/ready_trader_go/pubsub.py", line 136, in _subscribe_worker
    protocol.datagram_received(buffer[start:start + length], from_addr)
  File "/Users/nves/Downloads/pyready_trader_go/ready_trader_go/messages.py", line 212, in datagram_received
    self.on_datagram(typ, data, HEADER_SIZE, length)
  File "/Users/nves/Downloads/pyready_trader_go/ready_trader_go/base_auto_trader.py", line 69, in on_datagram
    self.on_order_book_update_message(inst, seq, *BOOK_PART.iter_unpack(data[ORDER_BOOK_HEADER_SIZE:]))
  File "/Users/nves/Downloads/pyready_trader_go/at_arb.py", line 101, in on_order_book_update_message
    if ((self.best_ask_trade - new_bid_price) / new_bid_price) > 0.01 and self.bid_id == 0 and new_bid_price != 0 and self.position < POSITION_LIMIT:
ZeroDivisionError: division by zero
2023-03-11 22:03:57,789 [INFO   ] [APP] closing event loop
2023-03-11 22:03:57,789 [INFO   ] [CONNECTION] fd=16 connection lost
2023-03-11 22:03:57,790 [ERROR  ] [asyncio] Exception in callback _SelectorSocketTransport._call_connection_lost(None)
handle: <Handle _SelectorSocketTransport._call_connection_lost(None)>
Traceback (most recent call last):
  File "/Library/Frameworks/Python.framework/Versions/3.10/lib/python3.10/asyncio/events.py", line 80, in _run
    self._context.run(self._callback, *self._args)
  File "/Library/Frameworks/Python.framework/Versions/3.10/lib/python3.10/asyncio/selector_events.py", line 984, in _call_connection_lost
    super()._call_connection_lost(exc)
  File "/Library/Frameworks/Python.framework/Versions/3.10/lib/python3.10/asyncio/selector_events.py", line 742, in _call_connection_lost
    self._protocol.connection_lost(exc)
  File "/Users/nves/Downloads/pyready_trader_go/ready_trader_go/base_auto_trader.py", line 59, in connection_lost
    Subscription.close(self)
  File "/Users/nves/Downloads/pyready_trader_go/ready_trader_go/messages.py", line 186, in close
    self._receiver_transport.close()
AttributeError: 'NoneType' object has no attribute 'close'
